#VRML_SIM R2023b utf8

EXTERNPROTO "https://raw.githubusercontent.com/cyberbotics/webots/R2023b/projects/objects/backgrounds/protos/TexturedBackground.proto"
EXTERNPROTO "https://raw.githubusercontent.com/cyberbotics/webots/R2023b/projects/objects/backgrounds/protos/TexturedBackgroundLight.proto"
EXTERNPROTO "https://raw.githubusercontent.com/cyberbotics/webots/R2023b/projects/objects/floors/protos/RectangleArena.proto"
EXTERNPROTO "https://raw.githubusercontent.com/cyberbotics/webots/R2023b/projects/objects/drinks/protos/Can.proto"
EXTERNPROTO "https://raw.githubusercontent.com/cyberbotics/webots/R2023b/projects/objects/fruits/protos/Apple.proto"
EXTERNPROTO "https://raw.githubusercontent.com/cyberbotics/webots/R2023b/projects/objects/kitchen/breakfast/protos/JamJar.proto"
EXTERNPROTO "https://raw.githubusercontent.com/cyberbotics/webots/R2023b/projects/objects/kitchen/breakfast/protos/BiscuitBox.proto"
EXTERNPROTO "https://raw.githubusercontent.com/cyberbotics/webots/R2023b/projects/objects/obstacles/protos/OilBarrel.proto"

WorldInfo {
  info [
    "Example use of a color Camera device with recognition capability."
  ]
  title "Camera Image Recognition"
}
Viewpoint {
  orientation 0.45182170121048415 0.18115506182862967 -0.8735216047065633 2.662125484144553
  position 0.9124970970887923 0.3726448052237924 1.3893275356823303
}
TexturedBackground {
}
TexturedBackgroundLight {
}
RectangleArena {
}
Can {
  translation -0.267626 -0.290201 0.060961710860935485
  rotation -1.255284180414606e-17 4.124109946487355e-17 1 3.14159
}
Apple {
  translation 0.221872 -0.277666 0.049764791394518226
}
Apple {
  translation 0.428276 -0.291241 0.049764791394518226
  name "apple(1)"
}
JamJar {
  translation -0.314033 0.288298 0
  rotation 0 0 -1 1.0472
  mass 0
}
BiscuitBox {
  translation 0.372915 -0.247523 0.09
  rotation 0.6947461893666473 -0.1861560507404686 -0.6947471893669199 -2.773495
  size 0.17 0.33 0.04
  mass 0
}
OilBarrel {
  translation 0.122868 0.40231 0.07
  rotation 0 0 1 1.5708
  height 0.14
  radius 0.06
}
OilBarrel {
  translation 0.182198 0.278521 0.07
  rotation 0 0 1 1.5708
  name "oil barrel(1)"
  height 0.14
  radius 0.06
}
OilBarrel {
  translation 0.318097 0.364876 0.07
  rotation 0 0 1 1.5708
  name "oil barrel(2)"
  height 0.14
  radius 0.06
}
OilBarrel {
  translation 0.368241 0.196561 0.07
  rotation 0 0 1 1.5708
  name "oil barrel(3)"
  height 0.14
  radius 0.06
}
Robot {
  translation -2.930664873441839e-06 4.7557827861741554e-05 -0.00023422047464424084
  rotation -0.014132289621328975 -0.052546393107793805 0.9985184800299992 -0.5261746918816241
  children [
    Pose {
      translation 0 0 0.0415
      rotation 0 0 1 -1.570796
      children [
        Shape {
          appearance PBRAppearance {
            baseColor 0.0820075 0.364731 0.8
            roughness 1
            metalness 0
          }
          geometry DEF BODY Cylinder {
            height 0.08
            radius 0.045
          }
        }
      ]
    }
    HingeJoint {
      jointParameters HingeJointParameters {
        position -38.8243462885607
        axis 0 1 0
        anchor 0 0 0.025
      }
      device [
        RotationalMotor {
          name "left wheel motor"
          consumptionFactor 70
        }
        PositionSensor {
          name "left wheel sensor"
        }
      ]
      endPoint Solid {
        translation 0 0.04499999999999999 0.025
        rotation 0.5410012670449563 -0.5410013850123168 -0.6439216803855162 1.9974116653217613
        children [
          DEF WHEEL Pose {
            rotation 0.577656895078166 0.5771968951617173 -0.5771968951617173 -2.093935
            children [
              Shape {
                appearance PBRAppearance {
                  baseColor 1 0 0
                  roughness 1
                  metalness 0
                }
                geometry Cylinder {
                  height 0.01
                  radius 0.025
                }
              }
            ]
          }
        ]
        name "left wheel"
        boundingObject USE WHEEL
        physics DEF PHYSICS_WHEEL Physics {
          density -1
          mass 0.05
        }
        linearVelocity -0.029040979372271198 0.017287078612814814 -2.7221522955777618e-08
        angularVelocity -0.7687961565933152 -1.2881187611639167 0.7547070245345177
      }
    }
    HingeJoint {
      jointParameters HingeJointParameters {
        position 38.824312926513116
        axis 0 1 0
        anchor 0 0 0.025
      }
      device [
        RotationalMotor {
          name "right wheel motor"
          consumptionFactor 70
        }
        PositionSensor {
          name "right wheel sensor"
        }
      ]
      endPoint Solid {
        translation 0 -0.045 0.025
        rotation -0.5050690358463531 0.5050689949158711 -0.6998646864958304 1.9203224523602895
        children [
          USE WHEEL
        ]
        name "right wheel"
        boundingObject USE WHEEL
        physics USE PHYSICS_WHEEL
        linearVelocity 0.02904095975237846 -0.01739090403689231 -6.79145330908312e-08
        angularVelocity 0.7687943946372539 1.2881140055877867 0.7547083997138192
      }
    }
    DistanceSensor {
      translation 0.042 0.02 0.063
      rotation 0 0 -1 -0.499205
      children [
        DEF SENSOR Pose {
          rotation 0.577656895078166 0.5771968951617173 -0.5771968951617173 -2.093935
          children [
            Shape {
              appearance PBRAppearance {
                baseColor 0.975691 0.981481 0.0252992
                roughness 1
                metalness 0
              }
              geometry Cylinder {
                height 0.004
                radius 0.008
              }
            }
          ]
        }
      ]
      name "ds0"
      lookupTable [
        0 1024 0
        0.05 1024 0
        0.15 0 0
      ]
      numberOfRays 2
      aperture 1
    }
    DistanceSensor {
      translation 0.042 -0.02 0.063
      rotation 0 0 1 -0.500795
      children [
        USE SENSOR
      ]
      name "ds1"
      lookupTable [
        0 1024 0
        0.05 1024 0
        0.15 0 0
      ]
      numberOfRays 2
      aperture 1
    }
    Shape {
      appearance PBRAppearance {
        baseColor 0.8 0.8 0.8
        baseColorMap ImageTexture {
          url [
            "https://raw.githubusercontent.com/cyberbotics/webots/R2023b/projects/samples/devices/worlds/textures/mybot.png"
          ]
        }
        roughness 0.5
        metalness 0
      }
      geometry IndexedFaceSet {
        coord Coordinate {
          point [
            0.0435 -0.015 0.038
            0.0435 -0.015 0.023
            0.0455 0 0.023
            0.0435 0.015 0.023
            0.0435 0.015 0.038
            0.0455 0 0.038
          ]
        }
        texCoord TextureCoordinate {
          point [
            0 0
            0.5 0
            1 0
            1 1
            0.5 1
            0 1
          ]
        }
        coordIndex [
          0, 1, 2, 5, -1, 5, 2, 3, 4, -1
        ]
        texCoordIndex [
          5, 0, 1, 4, -1, 4, 1, 2, 3, -1
        ]
        creaseAngle 0.9
      }
    }
    Camera {
      translation 0.04 0 0.0915
      children [
        Pose {
          translation -0.015 0 0
          rotation -0.5771968951617173 -0.577656895078166 -0.5771968951617173 -2.093935
          children [
            Shape {
              appearance PBRAppearance {
                roughness 1
                metalness 0
              }
              geometry Cylinder {
                height 0.03
                radius 0.01
              }
            }
          ]
        }
      ]
      fieldOfView 1.0472
      width 256
      height 128
      antiAliasing TRUE
      recognition Recognition {
        frameColor 0.929412 0.831373 0
        frameThickness 3
      }
    }
  ]
  name "MyBot"
  boundingObject Pose {
    translation 0 0 0.0415
    rotation 0 0 1 -1.570796
    children [
      USE BODY
    ]
  }
  physics Physics {
    density -1
    mass 0.5
  }
  controller "camera_recognition"
  linearVelocity 0.00017967218248893376 0.000249559554877204 -2.2311944178657295e-08
  angularVelocity -8.784032773609194e-07 -2.3746970343528455e-06 0.7506163258182116
}
